Workbook
Name quarterly_data: quarterly!$A$1:$J$227

Sheet data
A1: quarter_start | B1: quarter_end | C1: rtwi | D1: tot | E1: wui_au | F1: wui_au_sm | G1: us_rgdp | H1: au_rgdp | I1: au_inf_trim | J1: au_cpi | K1: ntwi | L1: aud_usd | M1: comm_price | N1: comm_price_bulk | O1: iron_ore | P1: coal | Q1: brent_crude | R1: natural_gas | S1: cash_rate | T1: fed_funds | U1: au_us_policy_rate | V1: au_2yr_yield | W1: us_2yr_yield | X1: au_us_2yr | Y1: au_10yr_yield | Z1: us_10yr_yield | AA1: au_us_10yr | AB1: vix | AC1: gepu | AD1: au_epu | AE1: gpr_global | AF1: gprt_global | AG1: gpra_global | AH1: gprc_au
A2: 25569 | B2: 25657 | C2: =IF(ISBLANK(VLOOKUP($A2,quarterly_data,MATCH(C$1,quarterly!$1:$1,FALSE),FALSE)),"NA",VLOOKUP($A2,quarterly_data,MATCH(C$1,quarterly!$1:$1,FALSE),FALSE)) -> NA | D2: =IF(ISBLANK(VLOOKUP($A2,quarterly_data,MATCH(D$1,quarterly!$1:$1,FALSE),FALSE)),"NA",VLOOKUP($A2,quarterly_data,MATCH(D$1,quarterly!$1:$1,FALSE),FALSE)) -> NA | E2: =IF(ISBLANK(VLOOKUP($A2,quarterly_data,MATCH(E$1,quarterly!$1:$1,FALSE),FALSE)),"NA",VLOOKUP($A2,quarterly_data,MATCH(E$1,quarterly!$1:$1,FALSE),FALSE)) -> 0 | F2: =IF(ISBLANK(VLOOKUP($A2,quarterly_data,MATCH(F$1,quarterly!$1:$1,FALSE),FALSE)),"NA",VLOOKUP($A2,quarterly_data,MATCH(F$1,quarterly!$1:$1,FALSE),FALSE)) -> 0.0111744 | G2: =IF(ISBLANK(VLOOKUP($A2,quarterly_data,MATCH(G$1,quarterly!$1:$1,FALSE),FALSE)),"NA",VLOOKUP($A2,quarterly_data,MATCH(G$1,quarterly!$1:$1,FALSE),FALSE)) -> 5300.652 | H2: =IF(ISBLANK(VLOOKUP($A2,quarterly_data,MATCH(H$1,quarterly!$1:$1,FALSE),FALSE)),"NA",VLOOKUP($A2,quarterly_data,MATCH(H$1,quarterly!$1:$1,FALSE),FALSE)) -> 136260 | I2: =IF(ISBLANK(VLOOKUP($A2,quarterly_data,MATCH(I$1,quarterly!$1:$1,FALSE),FALSE)),"NA",VLOOKUP($A2,quarterly_data,MATCH(I$1,quarterly!$1:$1,FALSE),FALSE)) -> NA | J2: =IF(ISBLANK(VLOOKUP($A2,quarterly_data,MATCH(J$1,quarterly!$1:$1,FALSE),FALSE)),"NA",VLOOKUP($A2,quarterly_data,MATCH(J$1,quarterly!$1:$1,FALSE),FALSE)) -> 6.69 | K2: =IF(COUNTIFS(monthly!C:C,"",monthly!$A:$A,">="&$A2,monthly!$B:$B,"<="&$B2)>0,"NA",AVERAGEIFS(monthly!C:C,monthly!$A:$A,">="&$A2,monthly!$B:$B,"<="&$B2)) -> NA | L2: =IF(COUNTIFS(monthly!D:D,"",monthly!$A:$A,">="&$A2,monthly!$B:$B,"<="&$B2)>0,"NA",AVERAGEIFS(monthly!D:D,monthly!$A:$A,">="&$A2,monthly!$B:$B,"<="&$B2)) -> 1.1197 | M2: =IF(COUNTIFS(monthly!E:E,"",monthly!$A:$A,">="&$A2,monthly!$B:$B,"<="&$B2)>0,"NA",AVERAGEIFS(monthly!E:E,monthly!$A:$A,">="&$A2,monthly!$B:$B,"<="&$B2)) -> NA | N2: =IF(COUNTIFS(monthly!F:F,"",monthly!$A:$A,">="&$A2,monthly!$B:$B,"<="&$B2)>0,"NA",AVERAGEIFS(monthly!F:F,monthly!$A:$A,">="&$A2,monthly!$B:$B,"<="&$B2)) -> NA | O2: =IF(COUNTIFS(monthly!G:G,"",monthly!$A:$A,">="&$A2,monthly!$B:$B,"<="&$B2)>0,"NA",AVERAGEIFS(monthly!G:G,monthly!$A:$A,">="&$A2,monthly!$B:$B,"<="&$B2)) -> 9.8 | P2: =IF(COUNTIFS(monthly!H:H,"",monthly!$A:$A,">="&$A2,monthly!$B:$B,"<="&$B2)>0,"NA",AVERAGEIFS(monthly!H:H,monthly!$A:$A,">="&$A2,monthly!$B:$B,"<="&$B2)) -> 7.8 | Q2: =IF(COUNTIFS(monthly!I:I,"",monthly!$A:$A,">="&$A2,monthly!$B:$B,"<="&$B2)>0,"NA",AVERAGEIFS(monthly!I:I,monthly!$A:$A,">="&$A2,monthly!$B:$B,"<="&$B2)) -> 1.2 | R2: =IF(COUNTIFS(monthly!J:J,"",monthly!$A:$A,">="&$A2,monthly!$B:$B,"<="&$B2)>0,"NA",AVERAGEIFS(monthly!J:J,monthly!$A:$A,">="&$A2,monthly!$B:$B,"<="&$B2)) -> NA | S2: =IF(COUNTIFS(monthly!K:K,"",monthly!$A:$A,">="&$A2,monthly!$B:$B,"<="&$B2)>0,"NA",AVERAGEIFS(monthly!K:K,monthly!$A:$A,">="&$A2,monthly!$B:$B,"<="&$B2)) -> NA | T2: =IF(COUNTIFS(monthly!L:L,"",monthly!$A:$A,">="&$A2,monthly!$B:$B,"<="&$B2)>0,"NA",AVERAGEIFS(monthly!L:L,monthly!$A:$A,">="&$A2,monthly!$B:$B,"<="&$B2)) -> 8.9774942 | U2: =IF(COUNTIFS(monthly!M:M,"",monthly!$A:$A,">="&$A2,monthly!$B:$B,"<="&$B2)>0,"NA",AVERAGEIFS(monthly!M:M,monthly!$A:$A,">="&$A2,monthly!$B:$B,"<="&$B2)) -> NA | V2: =IF(COUNTIFS(monthly!N:N,"",monthly!$A:$A,">="&$A2,monthly!$B:$B,"<="&$B2)>0,"NA",AVERAGEIFS(monthly!N:N,monthly!$A:$A,">="&$A2,monthly!$B:$B,"<="&$B2)) -> NA | W2: =IF(COUNTIFS(monthly!O:O,"",monthly!$A:$A,">="&$A2,monthly!$B:$B,"<="&$B2)>0,"NA",AVERAGEIFS(monthly!O:O,monthly!$A:$A,">="&$A2,monthly!$B:$B,"<="&$B2)) -> NA | X2: =IF(COUNTIFS(monthly!P:P,"",monthly!$A:$A,">="&$A2,monthly!$B:$B,"<="&$B2)>0,"NA",AVERAGEIFS(monthly!P:P,monthly!$A:$A,">="&$A2,monthly!$B:$B,"<="&$B2)) -> NA | Y2: =IF(COUNTIFS(monthly!Q:Q,"",monthly!$A:$A,">="&$A2,monthly!$B:$B,"<="&$B2)>0,"NA",AVERAGEIFS(monthly!Q:Q,monthly!$A:$A,">="&$A2,monthly!$B:$B,"<="&$B2)) -> 5.955 | Z2: =IF(COUNTIFS(monthly!R:R,"",monthly!$A:$A,">="&$A2,monthly!$B:$B,"<="&$B2)>0,"NA",AVERAGEIFS(monthly!R:R,monthly!$A:$A,">="&$A2,monthly!$B:$B,"<="&$B2)) -> 7.5165476 | AA2: =IF(COUNTIFS(monthly!S:S,"",monthly!$A:$A,">="&$A2,monthly!$B:$B,"<="&$B2)>0,"NA",AVERAGEIFS(monthly!S:S,monthly!$A:$A,">="&$A2,monthly!$B:$B,"<="&$B2)) -> -1.5615476 | AB2: =IF(COUNTIFS(monthly!T:T,"",monthly!$A:$A,">="&$A2,monthly!$B:$B,"<="&$B2)>0,"NA",AVERAGEIFS(monthly!T:T,monthly!$A:$A,">="&$A2,monthly!$B:$B,"<="&$B2)) -> NA | AC2: =IF(COUNTIFS(monthly!U:U,"",monthly!$A:$A,">="&$A2,monthly!$B:$B,"<="&$B2)>0,"NA",AVERAGEIFS(monthly!U:U,monthly!$A:$A,">="&$A2,monthly!$B:$B,"<="&$B2)) -> NA | AD2: =IF(COUNTIFS(monthly!V:V,"",monthly!$A:$A,">="&$A2,monthly!$B:$B,"<="&$B2)>0,"NA",AVERAGEIFS(monthly!V:V,monthly!$A:$A,">="&$A2,monthly!$B:$B,"<="&$B2)) -> NA | AE2: =IF(COUNTIFS(monthly!W:W,"",monthly!$A:$A,">="&$A2,monthly!$B:$B,"<="&$B2)>0,"NA",AVERAGEIFS(monthly!W:W,monthly!$A:$A,">="&$A2,monthly!$B:$B,"<="&$B2)) -> NA | AF2: =IF(COUNTIFS(monthly!X:X,"",monthly!$A:$A,">="&$A2,monthly!$B:$B,"<="&$B2)>0,"NA",AVERAGEIFS(monthly!X:X,monthly!$A:$A,">="&$A2,monthly!$B:$B,"<="&$B2)) -> NA | AG2: =IF(COUNTIFS(monthly!Y:Y,"",monthly!$A:$A,">="&$A2,monthly!$B:$B,"<="&$B2)>0,"NA",AVERAGEIFS(monthly!Y:Y,monthly!$A:$A,">="&$A2,monthly!$B:$B,"<="&$B2)) -> NA | AH2: =IF(COUNTIFS(monthly!Z:Z,"",monthly!$A:$A,">="&$A2,monthly!$B:$B,"<="&$B2)>0,"NA",AVERAGEIFS(monthly!Z:Z,monthly!$A:$A,">="&$A2,monthly!$B:$B,"<="&$B2)) -> NA
A3: 25659 | B3: 25749 | C3: =IF(ISBLANK(VLOOKUP($A3,quarterly_data,MATCH(C$1,quarterly!$1:$1,FALSE),FALSE)),"NA",VLOOKUP($A3,quarterly_data,MATCH(C$1,quarterly!$1:$1,FALSE),FALSE)) -> 146.45132 | D3: =IF(ISBLANK(VLOOKUP($A3,quarterly_data,MATCH(D$1,quarterly!$1:$1,FALSE),FALSE)),"NA",VLOOKUP($A3,quarterly_data,MATCH(D$1,quarterly!$1:$1,FALSE),FALSE)) -> 59.1 | E3: =IF(ISBLANK(VLOOKUP($A3,quarterly_data,MATCH(E$1,quarterly!$1:$1,FALSE),FALSE)),"NA",VLOOKUP($A3,quarterly_data,MATCH(E$1,quarterly!$1:$1,FALSE),FALSE)) -> 0.2192982 | F3: =IF(ISBLANK(VLOOKUP($A3,quarterly_data,MATCH(F$1,quarterly!$1:$1,FALSE),FALSE)),"NA",VLOOKUP($A3,quarterly_data,MATCH(F$1,quarterly!$1:$1,FALSE),FALSE)) -> 0.0438596 | G3: =IF(ISBLANK(VLOOKUP($A3,quarterly_data,MATCH(G$1,quarterly!$1:$1,FALSE),FALSE)),"NA",VLOOKUP($A3,quarterly_data,MATCH(G$1,quarterly!$1:$1,FALSE),FALSE)) -> 5308.164 | H3: =IF(ISBLANK(VLOOKUP($A3,quarterly_data,MATCH(H$1,quarterly!$1:$1,FALSE),FALSE)),"NA",VLOOKUP($A3,quarterly_data,MATCH(H$1,quarterly!$1:$1,FALSE),FALSE)) -> 139021 | I3: =IF(ISBLANK(VLOOKUP($A3,quarterly_data,MATCH(I$1,quarterly!$1:$1,FALSE),FALSE)),"NA",VLOOKUP($A3,quarterly_data,MATCH(I$1,quarterly!$1:$1,FALSE),FALSE)) -> NA | J3: =IF(ISBLANK(VLOOKUP($A3,quarterly_data,MATCH(J$1,quarterly!$1:$1,FALSE),FALSE)),"NA",VLOOKUP($A3,quarterly_data,MATCH(J$1,quarterly!$1:$1,FALSE),FALSE)) -> 6.77 | K3: =IF(COUNTIFS(monthly!C:C,"",monthly!$A:$A,">="&$A3,monthly!$B:$B,"<="&$B3)>0,"NA",AVERAGEIFS(monthly!C:C,monthly!$A:$A,">="&$A3,monthly!$B:$B,"<="&$B3)) -> NA | L3: =IF(COUNTIFS(monthly!D:D,"",monthly!$A:$A,">="&$A3,monthly!$B:$B,"<="&$B3)>0,"NA",AVERAGEIFS(monthly!D:D,monthly!$A:$A,">="&$A3,monthly!$B:$B,"<="&$B3)) -> 1.1183667 | M3: =IF(COUNTIFS(monthly!E:E,"",monthly!$A:$A,">="&$A3,monthly!$B:$B,"<="&$B3)>0,"NA",AVERAGEIFS(monthly!E:E,monthly!$A:$A,">="&$A3,monthly!$B:$B,"<="&$B3)) -> NA | N3: =IF(COUNTIFS(monthly!F:F,"",monthly!$A:$A,">="&$A3,monthly!$B:$B,"<="&$B3)>0,"NA",AVERAGEIFS(monthly!F:F,monthly!$A:$A,">="&$A3,monthly!$B:$B,"<="&$B3)) -> NA | O3: =IF(COUNTIFS(monthly!G:G,"",monthly!$A:$A,">="&$A3,monthly!$B:$B,"<="&$B3)>0,"NA",AVERAGEIFS(monthly!G:G,monthly!$A:$A,">="&$A3,monthly!$B:$B,"<="&$B3)) -> 9.8 | P3: =IF(COUNTIFS(monthly!H:H,"",monthly!$A:$A,">="&$A3,monthly!$B:$B,"<="&$B3)>0,"NA",AVERAGEIFS(monthly!H:H,monthly!$A:$A,">="&$A3,monthly!$B:$B,"<="&$B3)) -> 7.8 | Q3: =IF(COUNTIFS(monthly!I:I,"",monthly!$A:$A,">="&$A3,monthly!$B:$B,"<="&$B3)>0,"NA",AVERAGEIFS(monthly!I:I,monthly!$A:$A,">="&$A3,monthly!$B:$B,"<="&$B3)) -> 1.2 | R3: =IF(COUNTIFS(monthly!J:J,"",monthly!$A:$A,">="&$A3,monthly!$B:$B,"<="&$B3)>0,"NA",AVERAGEIFS(monthly!J:J,monthly!$A:$A,">="&$A3,monthly!$B:$B,"<="&$B3)) -> NA | S3: =IF(COUNTIFS(monthly!K:K,"",monthly!$A:$A,">="&$A3,monthly!$B:$B,"<="&$B3)>0,"NA",AVERAGEIFS(monthly!K:K,monthly!$A:$A,">="&$A3,monthly!$B:$B,"<="&$B3)) -> NA | T3: =IF(COUNTIFS(monthly!L:L,"",monthly!$A:$A,">="&$A3,monthly!$B:$B,"<="&$B3)>0,"NA",AVERAGEIFS(monthly!L:L,monthly!$A:$A,">="&$A3,monthly!$B:$B,"<="&$B3)) -> 7.882595 | U3: =IF(COUNTIFS(monthly!M:M,"",monthly!$A:$A,">="&$A3,monthly!$B:$B,"<="&$B3)>0,"NA",AVERAGEIFS(monthly!M:M,monthly!$A:$A,">="&$A3,monthly!$B:$B,"<="&$B3)) -> NA | V3: =IF(COUNTIFS(monthly!N:N,"",monthly!$A:$A,">="&$A3,monthly!$B:$B,"<="&$B3)>0,"NA",AVERAGEIFS(monthly!N:N,monthly!$A:$A,">="&$A3,monthly!$B:$B,"<="&$B3)) -> NA | W3: =IF(COUNTIFS(monthly!O:O,"",monthly!$A:$A,">="&$A3,monthly!$B:$B,"<="&$B3)>0,"NA",AVERAGEIFS(monthly!O:O,monthly!$A:$A,">="&$A3,monthly!$B:$B,"<="&$B3)) -> NA | X3: =IF(COUNTIFS(monthly!P:P,"",monthly!$A:$A,">="&$A3,monthly!$B:$B,"<="&$B3)>0,"NA",AVERAGEIFS(monthly!P:P,monthly!$A:$A,">="&$A3,monthly!$B:$B,"<="&$B3)) -> NA | Y3: =IF(COUNTIFS(monthly!Q:Q,"",monthly!$A:$A,">="&$A3,monthly!$B:$B,"<="&$B3)>0,"NA",AVERAGEIFS(monthly!Q:Q,monthly!$A:$A,">="&$A3,monthly!$B:$B,"<="&$B3)) -> 6.8833333 | Z3: =IF(COUNTIFS(monthly!R:R,"",monthly!$A:$A,">="&$A3,monthly!$B:$B,"<="&$B3)>0,"NA",AVERAGEIFS(monthly!R:R,monthly!$A:$A,">="&$A3,monthly!$B:$B,"<="&$B3)) -> 7.7129726 | AA3: =IF(COUNTIFS(monthly!S:S,"",monthly!$A:$A,">="&$A3,monthly!$B:$B,"<="&$B3)>0,"NA",AVERAGEIFS(monthly!S:S,monthly!$A:$A,">="&$A3,monthly!$B:$B,"<="&$B3)) -> -0.82963925 | AB3: =IF(COUNTIFS(monthly!T:T,"",monthly!$A:$A,">="&$A3,monthly!$B:$B,"<="&$B3)>0,"NA",AVERAGEIFS(monthly!T:T,monthly!$A:$A,">="&$A3,monthly!$B:$B,"<="&$B3)) -> NA | AC3: =IF(COUNTIFS(monthly!U:U,"",monthly!$A:$A,">="&$A3,monthly!$B:$B,"<="&$B3)>0,"NA",AVERAGEIFS(monthly!U:U,monthly!$A:$A,">="&$A3,monthly!$B:$B,"<="&$B3)) -> NA | AD3: =IF(COUNTIFS(monthly!V:V,"",monthly!$A:$A,">="&$A3,monthly!$B:$B,"<="&$B3)>0,"NA",AVERAGEIFS(monthly!V:V,monthly!$A:$A,">="&$A3,monthly!$B:$B,"<="&$B3)) -> NA | AE3: =IF(COUNTIFS(monthly!W:W,"",monthly!$A:$A,">="&$A3,monthly!$B:$B,"<="&$B3)>0,"NA",AVERAGEIFS(monthly!W:W,monthly!$A:$A,">="&$A3,monthly!$B:$B,"<="&$B3)) -> NA | AF3: =IF(COUNTIFS(monthly!X:X,"",monthly!$A:$A,">="&$A3,monthly!$B:$B,"<="&$B3)>0,"NA",AVERAGEIFS(monthly!X:X,monthly!$A:$A,">="&$A3,monthly!$B:$B,"<="&$B3)) -> NA | AG3: =IF(COUNTIFS(monthly!Y:Y,"",monthly!$A:$A,">="&$A3,monthly!$B:$B,"<="&$B3)>0,"NA",AVERAGEIFS(monthly!Y:Y,monthly!$A:$A,">="&$A3,monthly!$B:$B,"<="&$B3)) -> NA | AH3: =IF(COUNTIFS(monthly!Z:Z,"",monthly!$A:$A,">="&$A3,monthly!$B:$B,"<="&$B3)>0,"NA",AVERAGEIFS(monthly!Z:Z,monthly!$A:$A,">="&$A3,monthly!$B:$B,"<="&$B3)) -> NA
A4: 25750 | B4: 25841 | C4: =IF(ISBLANK(VLOOKUP($A4,quarterly_data,MATCH(C$1,quarterly!$1:$1,FALSE),FALSE)),"NA",VLOOKUP($A4,quarterly_data,MATCH(C$1,quarterly!$1:$1,FALSE),FALSE)) -> 144.54268 | D4: =IF(ISBLANK(VLOOKUP($A4,quarterly_data,MATCH(D$1,quarterly!$1:$1,FALSE),FALSE)),"NA",VLOOKUP($A4,quarterly_data,MATCH(D$1,quarterly!$1:$1,FALSE),FALSE)) -> 58.1 | E4: =IF(ISBLANK(VLOOKUP($A4,quarterly_data,MATCH(E$1,quarterly!$1:$1,FALSE),FALSE)),"NA",VLOOKUP($A4,quarterly_data,MATCH(E$1,quarterly!$1:$1,FALSE),FALSE)) -> 0 | F4: =IF(ISBLANK(VLOOKUP($A4,quarterly_data,MATCH(F$1,quarterly!$1:$1,FALSE),FALSE)),"NA",VLOOKUP($A4,quarterly_data,MATCH(F$1,quarterly!$1:$1,FALSE),FALSE)) -> 0.0219298 | G4: =IF(ISBLANK(VLOOKUP($A4,quarterly_data,MATCH(G$1,quarterly!$1:$1,FALSE),FALSE)),"NA",VLOOKUP($A4,quarterly_data,MATCH(G$1,quarterly!$1:$1,FALSE),FALSE)) -> 5357.077 | H4: =IF(ISBLANK(VLOOKUP($A4,quarterly_data,MATCH(H$1,quarterly!$1:$1,FALSE),FALSE)),"NA",VLOOKUP($A4,quarterly_data,MATCH(H$1,quarterly!$1:$1,FALSE),FALSE)) -> 138729 | I4: =IF(ISBLANK(VLOOKUP($A4,quarterly_data,MATCH(I$1,quarterly!$1:$1,FALSE),FALSE)),"NA",VLOOKUP($A4,quarterly_data,MATCH(I$1,quarterly!$1:$1,FALSE),FALSE)) -> NA | J4: =IF(ISBLANK(VLOOKUP($A4,quarterly_data,MATCH(J$1,quarterly!$1:$1,FALSE),FALSE)),"NA",VLOOKUP($A4,quarterly_data,MATCH(J$1,quarterly!$1:$1,FALSE),FALSE)) -> 6.8 | K4: =IF(COUNTIFS(monthly!C:C,"",monthly!$A:$A,">="&$A4,monthly!$B:$B,"<="&$B4)>0,"NA",AVERAGEIFS(monthly!C:C,monthly!$A:$A,">="&$A4,monthly!$B:$B,"<="&$B4)) -> 99.233333 | L4: =IF(COUNTIFS(monthly!D:D,"",monthly!$A:$A,">="&$A4,monthly!$B:$B,"<="&$B4)>0,"NA",AVERAGEIFS(monthly!D:D,monthly!$A:$A,">="&$A4,monthly!$B:$B,"<="&$B4)) -> 1.1117333 | M4: =IF(COUNTIFS(monthly!E:E,"",monthly!$A:$A,">="&$A4,monthly!$B:$B,"<="&$B4)>0,"NA",AVERAGEIFS(monthly!E:E,monthly!$A:$A,">="&$A4,monthly!$B:$B,"<="&$B4)) -> NA | N4: =IF(COUNTIFS(monthly!F:F,"",monthly!$A:$A,">="&$A4,monthly!$B:$B,"<="&$B4)>0,"NA",AVERAGEIFS(monthly!F:F,monthly!$A:$A,">="&$A4,monthly!$B:$B,"<="&$B4)) -> NA | O4: =IF(COUNTIFS(monthly!G:G,"",monthly!$A:$A,">="&$A4,monthly!$B:$B,"<="&$B4)>0,"NA",AVERAGEIFS(monthly!G:G,monthly!$A:$A,">="&$A4,monthly!$B:$B,"<="&$B4)) -> 9.8 | P4: =IF(COUNTIFS(monthly!H:H,"",monthly!$A:$A,">="&$A4,monthly!$B:$B,"<="&$B4)>0,"NA",AVERAGEIFS(monthly!H:H,monthly!$A:$A,">="&$A4,monthly!$B:$B,"<="&$B4)) -> 7.8 | Q4: =IF(COUNTIFS(monthly!I:I,"",monthly!$A:$A,">="&$A4,monthly!$B:$B,"<="&$B4)>0,"NA",AVERAGEIFS(monthly!I:I,monthly!$A:$A,">="&$A4,monthly!$B:$B,"<="&$B4)) -> 1.2 | R4: =IF(COUNTIFS(monthly!J:J,"",monthly!$A:$A,">="&$A4,monthly!$B:$B,"<="&$B4)>0,"NA",AVERAGEIFS(monthly!J:J,monthly!$A:$A,">="&$A4,monthly!$B:$B,"<="&$B4)) -> NA | S4: =IF(COUNTIFS(monthly!K:K,"",monthly!$A:$A,">="&$A4,monthly!$B:$B,"<="&$B4)>0,"NA",AVERAGEIFS(monthly!K:K,monthly!$A:$A,">="&$A4,monthly!$B:$B,"<="&$B4)) -> NA | T4: =IF(COUNTIFS(monthly!L:L,"",monthly!$A:$A,">="&$A4,monthly!$B:$B,"<="&$B4)>0,"NA",AVERAGEIFS(monthly!L:L,monthly!$A:$A,">="&$A4,monthly!$B:$B,"<="&$B4)) -> 6.7065556 | U4: =IF(COUNTIFS(monthly!M:M,"",monthly!$A:$A,">="&$A4,monthly!$B:$B,"<="&$B4)>0,"NA",AVERAGEIFS(monthly!M:M,monthly!$A:$A,">="&$A4,monthly!$B:$B,"<="&$B4)) -> NA | V4: =IF(COUNTIFS(monthly!N:N,"",monthly!$A:$A,">="&$A4,monthly!$B:$B,"<="&$B4)>0,"NA",AVERAGEIFS(monthly!N:N,monthly!$A:$A,">="&$A4,monthly!$B:$B,"<="&$B4)) -> NA | W4: =IF(COUNTIFS(monthly!O:O,"",monthly!$A:$A,">="&$A4,monthly!$B:$B,"<="&$B4)>0,"NA",AVERAGEIFS(monthly!O:O,monthly!$A:$A,">="&$A4,monthly!$B:$B,"<="&$B4)) -> NA | X4: =IF(COUNTIFS(monthly!P:P,"",monthly!$A:$A,">="&$A4,monthly!$B:$B,"<="&$B4)>0,"NA",AVERAGEIFS(monthly!P:P,monthly!$A:$A,">="&$A4,monthly!$B:$B,"<="&$B4)) -> NA | Y4: =IF(COUNTIFS(monthly!Q:Q,"",monthly!$A:$A,">="&$A4,monthly!$B:$B,"<="&$B4)>0,"NA",AVERAGEIFS(monthly!Q:Q,monthly!$A:$A,">="&$A4,monthly!$B:$B,"<="&$B4)) -> 6.8766667 | Z4: =IF(COUNTIFS(monthly!R:R,"",monthly!$A:$A,">="&$A4,monthly!$B:$B,"<="&$B4)>0,"NA",AVERAGEIFS(monthly!R:R,monthly!$A:$A,">="&$A4,monthly!$B:$B,"<="&$B4)) -> 7.4579798 | AA4: =IF(COUNTIFS(monthly!S:S,"",monthly!$A:$A,">="&$A4,monthly!$B:$B,"<="&$B4)>0,"NA",AVERAGEIFS(monthly!S:S,monthly!$A:$A,">="&$A4,monthly!$B:$B,"<="&$B4)) -> -0.58131313 | AB4: =IF(COUNTIFS(monthly!T:T,"",monthly!$A:$A,">="&$A4,monthly!$B:$B,"<="&$B4)>0,"NA",AVERAGEIFS(monthly!T:T,monthly!$A:$A,">="&$A4,monthly!$B:$B,"<="&$B4)) -> NA | AC4: =IF(COUNTIFS(monthly!U:U,"",monthly!$A:$A,">="&$A4,monthly!$B:$B,"<="&$B4)>0,"NA",AVERAGEIFS(monthly!U:U,monthly!$A:$A,">="&$A4,monthly!$B:$B,"<="&$B4)) -> NA | AD4: =IF(COUNTIFS(monthly!V:V,"",monthly!$A:$A,">="&$A4,monthly!$B:$B,"<="&$B4)>0,"NA",AVERAGEIFS(monthly!V:V,monthly!$A:$A,">="&$A4,monthly!$B:$B,"<="&$B4)) -> NA | AE4: =IF(COUNTIFS(monthly!W:W,"",monthly!$A:$A,">="&$A4,monthly!$B:$B,"<="&$B4)>0,"NA",AVERAGEIFS(monthly!W:W,monthly!$A:$A,">="&$A4,monthly!$B:$B,"<="&$B4)) -> NA | AF4: =IF(COUNTIFS(monthly!X:X,"",monthly!$A:$A,">="&$A4,monthly!$B:$B,"<="&$B4)>0,"NA",AVERAGEIFS(monthly!X:X,monthly!$A:$A,">="&$A4,monthly!$B:$B,"<="&$B4)) -> NA | AG4: =IF(COUNTIFS(monthly!Y:Y,"",monthly!$A:$A,">="&$A4,monthly!$B:$B,"<="&$B4)>0,"NA",AVERAGEIFS(monthly!Y:Y,monthly!$A:$A,">="&$A4,monthly!$B:$B,"<="&$B4)) -> NA | AH4: =IF(COUNTIFS(monthly!Z:Z,"",monthly!$A:$A,">="&$A4,monthly!$B:$B,"<="&$B4)>0,"NA",AVERAGEIFS(monthly!Z:Z,monthly!$A:$A,">="&$A4,monthly!$B:$B,"<="&$B4)) -> NA
A5: 25842 | B5: 25932 | C5: =IF(ISBLANK(VLOOKUP($A5,quarterly_data,MATCH(C$1,quarterly!$1:$1,FALSE),FALSE)),"NA",VLOOKUP($A5,quarterly_data,MATCH(C$1,quarterly!$1:$1,FALSE),FALSE)) -> 145.17265 | D5: =IF(ISBLANK(VLOOKUP($A5,quarterly_data,MATCH(D$1,quarterly!$1:$1,FALSE),FALSE)),"NA",VLOOKUP($A5,quarterly_data,MATCH(D$1,quarterly!$1:$1,FALSE),FALSE)) -> 55.6 | E5: =IF(ISBLANK(VLOOKUP($A5,quarterly_data,MATCH(E$1,quarterly!$1:$1,FALSE),FALSE)),"NA",VLOOKUP($A5,quarterly_data,MATCH(E$1,quarterly!$1:$1,FALSE),FALSE)) -> 0.3646308 | F5: =IF(ISBLANK(VLOOKUP($A5,quarterly_data,MATCH(F$1,quarterly!$1:$1,FALSE),FALSE)),"NA",VLOOKUP($A5,quarterly_data,MATCH(F$1,quarterly!$1:$1,FALSE),FALSE)) -> 0.0802361 | G5: =IF(ISBLANK(VLOOKUP($A5,quarterly_data,MATCH(G$1,quarterly!$1:$1,FALSE),FALSE)),"NA",VLOOKUP($A5,quarterly_data,MATCH(G$1,quarterly!$1:$1,FALSE),FALSE)) -> 5299.672 | H5: =IF(ISBLANK(VLOOKUP($A5,quarterly_data,MATCH(H$1,quarterly!$1:$1,FALSE),FALSE)),"NA",VLOOKUP($A5,quarterly_data,MATCH(H$1,quarterly!$1:$1,FALSE),FALSE)) -> 139332 | I5: =IF(ISBLANK(VLOOKUP($A5,quarterly_data,MATCH(I$1,quarterly!$1:$1,FALSE),FALSE)),"NA",VLOOKUP($A5,quarterly_data,MATCH(I$1,quarterly!$1:$1,FALSE),FALSE)) -> NA | J5: =IF(ISBLANK(VLOOKUP($A5,quarterly_data,MATCH(J$1,quarterly!$1:$1,FALSE),FALSE)),"NA",VLOOKUP($A5,quarterly_data,MATCH(J$1,quarterly!$1:$1,FALSE),FALSE)) -> 6.92 | K5: =IF(COUNTIFS(monthly!C:C,"",monthly!$A:$A,">="&$A5,monthly!$B:$B,"<="&$B5)>0,"NA",AVERAGEIFS(monthly!C:C,monthly!$A:$A,">="&$A5,monthly!$B:$B,"<="&$B5)) -> 99.2 | L5: =IF(COUNTIFS(monthly!D:D,"",monthly!$A:$A,">="&$A5,monthly!$B:$B,"<="&$B5)>0,"NA",AVERAGEIFS(monthly!D:D,monthly!$A:$A,">="&$A5,monthly!$B:$B,"<="&$B5)) -> 1.1131 | M5: =IF(COUNTIFS(monthly!E:E,"",monthly!$A:$A,">="&$A5,monthly!$B:$B,"<="&$B5)>0,"NA",AVERAGEIFS(monthly!E:E,monthly!$A:$A,">="&$A5,monthly!$B:$B,"<="&$B5)) -> NA | N5: =IF(COUNTIFS(monthly!F:F,"",monthly!$A:$A,">="&$A5,monthly!$B:$B,"<="&$B5)>0,"NA",AVERAGEIFS(monthly!F:F,monthly!$A:$A,">="&$A5,monthly!$B:$B,"<="&$B5)) -> NA | O5: =IF(COUNTIFS(monthly!G:G,"",monthly!$A:$A,">="&$A5,monthly!$B:$B,"<="&$B5)>0,"NA",AVERAGEIFS(monthly!G:G,monthly!$A:$A,">="&$A5,monthly!$B:$B,"<="&$B5)) -> 9.8 | P5: =IF(COUNTIFS(monthly!H:H,"",monthly!$A:$A,">="&$A5,monthly!$B:$B,"<="&$B5)>0,"NA",AVERAGEIFS(monthly!H:H,monthly!$A:$A,">="&$A5,monthly!$B:$B,"<="&$B5)) -> 7.8 | Q5: =IF(COUNTIFS(monthly!I:I,"",monthly!$A:$A,">="&$A5,monthly!$B:$B,"<="&$B5)>0,"NA",AVERAGEIFS(monthly!I:I,monthly!$A:$A,">="&$A5,monthly!$B:$B,"<="&$B5)) -> 1.2 | R5: =IF(COUNTIFS(monthly!J:J,"",monthly!$A:$A,">="&$A5,monthly!$B:$B,"<="&$B5)>0,"NA",AVERAGEIFS(monthly!J:J,monthly!$A:$A,">="&$A5,monthly!$B:$B,"<="&$B5)) -> NA | S5: =IF(COUNTIFS(monthly!K:K,"",monthly!$A:$A,">="&$A5,monthly!$B:$B,"<="&$B5)>0,"NA",AVERAGEIFS(monthly!K:K,monthly!$A:$A,">="&$A5,monthly!$B:$B,"<="&$B5)) -> NA | T5: =IF(COUNTIFS(monthly!L:L,"",monthly!$A:$A,">="&$A5,monthly!$B:$B,"<="&$B5)>0,"NA",AVERAGEIFS(monthly!L:L,monthly!$A:$A,">="&$A5,monthly!$B:$B,"<="&$B5)) -> 5.9026022 | U5: =IF(COUNTIFS(monthly!M:M,"",monthly!$A:$A,">="&$A5,monthly!$B:$B,"<="&$B5)>0,"NA",AVERAGEIFS(monthly!M:M,monthly!$A:$A,">="&$A5,monthly!$B:$B,"<="&$B5)) -> NA | V5: =IF(COUNTIFS(monthly!N:N,"",monthly!$A:$A,">="&$A5,monthly!$B:$B,"<="&$B5)>0,"NA",AVERAGEIFS(monthly!N:N,monthly!$A:$A,">="&$A5,monthly!$B:$B,"<="&$B5)) -> NA | W5: =IF(COUNTIFS(monthly!O:O,"",monthly!$A:$A,">="&$A5,monthly!$B:$B,"<="&$B5)>0,"NA",AVERAGEIFS(monthly!O:O,monthly!$A:$A,">="&$A5,monthly!$B:$B,"<="&$B5)) -> NA | X5: =IF(COUNTIFS(monthly!P:P,"",monthly!$A:$A,">="&$A5,monthly!$B:$B,"<="&$B5)>0,"NA",AVERAGEIFS(monthly!P:P,monthly!$A:$A,">="&$A5,monthly!$B:$B,"<="&$B5)) -> NA | Y5: =IF(COUNTIFS(monthly!Q:Q,"",monthly!$A:$A,">="&$A5,monthly!$B:$B,"<="&$B5)>0,"NA",AVERAGEIFS(monthly!Q:Q,monthly!$A:$A,">="&$A5,monthly!$B:$B,"<="&$B5)) -> 6.855 | Z5: =IF(COUNTIFS(monthly!R:R,"",monthly!$A:$A,">="&$A5,monthly!$B:$B,"<="&$B5)>0,"NA",AVERAGEIFS(monthly!R:R,monthly!$A:$A,">="&$A5,monthly!$B:$B,"<="&$B5)) -> 7.0838889 | AA5: =IF(COUNTIFS(monthly!S:S,"",monthly!$A:$A,">="&$A5,monthly!$B:$B,"<="&$B5)>0,"NA",AVERAGEIFS(monthly!S:S,monthly!$A:$A,">="&$A5,monthly!$B:$B,"<="&$B5)) -> -0.22888889 | AB5: =IF(COUNTIFS(monthly!T:T,"",monthly!$A:$A,">="&$A5,monthly!$B:$B,"<="&$B5)>0,"NA",AVERAGEIFS(monthly!T:T,monthly!$A:$A,">="&$A5,monthly!$B:$B,"<="&$B5)) -> NA | AC5: =IF(COUNTIFS(monthly!U:U,"",monthly!$A:$A,">="&$A5,monthly!$B:$B,"<="&$B5)>0,"NA",AVERAGEIFS(monthly!U:U,monthly!$A:$A,">="&$A5,monthly!$B:$B,"<="&$B5)) -> NA | AD5: =IF(COUNTIFS(monthly!V:V,"",monthly!$A:$A,">="&$A5,monthly!$B:$B,"<="&$B5)>0,"NA",AVERAGEIFS(monthly!V:V,monthly!$A:$A,">="&$A5,monthly!$B:$B,"<="&$B5)) -> NA | AE5: =IF(COUNTIFS(monthly!W:W,"",monthly!$A:$A,">="&$A5,monthly!$B:$B,"<="&$B5)>0,"NA",AVERAGEIFS(monthly!W:W,monthly!$A:$A,">="&$A5,monthly!$B:$B,"<="&$B5)) -> NA | AF5: =IF(COUNTIFS(monthly!X:X,"",monthly!$A:$A,">="&$A5,monthly!$B:$B,"<="&$B5)>0,"NA",AVERAGEIFS(monthly!X:X,monthly!$A:$A,">="&$A5,monthly!$B:$B,"<="&$B5)) -> NA | AG5: =IF(COUNTIFS(monthly!Y:Y,"",monthly!$A:$A,">="&$A5,monthly!$B:$B,"<="&$B5)>0,"NA",AVERAGEIFS(monthly!Y:Y,monthly!$A:$A,">="&$A5,monthly!$B:$B,"<="&$B5)) -> NA | AH5: =IF(COUNTIFS(monthly!Z:Z,"",monthly!$A:$A,">="&$A5,monthly!$B:$B,"<="&$B5)>0,"NA",AVERAGEIFS(monthly!Z:Z,monthly!$A:$A,">="&$A5,monthly!$B:$B,"<="&$B5)) -> NA
A6: 25934 | B6: 26022 | C6: =IF(ISBLANK(VLOOKUP($A6,quarterly_data,MATCH(C$1,quarterly!$1:$1,FALSE),FALSE)),"NA",VLOOKUP($A6,quarterly_data,MATCH(C$1,quarterly!$1:$1,FALSE),FALSE)) -> 146.01779 | D6: =IF(ISBLANK(VLOOKUP($A6,quarterly_data,MATCH(D$1,quarterly!$1:$1,FALSE),FALSE)),"NA",VLOOKUP($A6,quarterly_data,MATCH(D$1,quarterly!$1:$1,FALSE),FALSE)) -> 55.9 | E6: =IF(ISBLANK(VLOOKUP($A6,quarterly_data,MATCH(E$1,quarterly!$1:$1,FALSE),FALSE)),"NA",VLOOKUP($A6,quarterly_data,MATCH(E$1,quarterly!$1:$1,FALSE),FALSE)) -> 0.655308 | F6: =IF(ISBLANK(VLOOKUP($A6,quarterly_data,MATCH(F$1,quarterly!$1:$1,FALSE),FALSE)),"NA",VLOOKUP($A6,quarterly_data,MATCH(F$1,quarterly!$1:$1,FALSE),FALSE)) -> 0.1675247 | G6: =IF(ISBLANK(VLOOKUP($A6,quarterly_data,MATCH(G$1,quarterly!$1:$1,FALSE),FALSE)),"NA",VLOOKUP($A6,quarterly_data,MATCH(G$1,quarterly!$1:$1,FALSE),FALSE)) -> 5443.619 | H6: =IF(ISBLANK(VLOOKUP($A6,quarterly_data,MATCH(H$1,quarterly!$1:$1,FALSE),FALSE)),"NA",VLOOKUP($A6,quarterly_data,MATCH(H$1,quarterly!$1:$1,FALSE),FALSE)) -> 141071 | I6: =IF(ISBLANK(VLOOKUP($A6,quarterly_data,MATCH(I$1,quarterly!$1:$1,FALSE),FALSE)),"NA",VLOOKUP($A6,quarterly_data,MATCH(I$1,quarterly!$1:$1,FALSE),FALSE)) -> NA | J6: =IF(ISBLANK(VLOOKUP($A6,quarterly_data,MATCH(J$1,quarterly!$1:$1,FALSE),FALSE)),"NA",VLOOKUP($A6,quarterly_data,MATCH(J$1,quarterly!$1:$1,FALSE),FALSE)) -> 7 | K6: =IF(COUNTIFS(monthly!C:C,"",monthly!$A:$A,">="&$A6,monthly!$B:$B,"<="&$B6)>0,"NA",AVERAGEIFS(monthly!C:C,monthly!$A:$A,">="&$A6,monthly!$B:$B,"<="&$B6)) -> 100 | L6: =IF(COUNTIFS(monthly!D:D,"",monthly!$A:$A,">="&$A6,monthly!$B:$B,"<="&$B6)>0,"NA",AVERAGEIFS(monthly!D:D,monthly!$A:$A,">="&$A6,monthly!$B:$B,"<="&$B6)) -> 1.12595 | M6: =IF(COUNTIFS(monthly!E:E,"",monthly!$A:$A,">="&$A6,monthly!$B:$B,"<="&$B6)>0,"NA",AVERAGEIFS(monthly!E:E,monthly!$A:$A,">="&$A6,monthly!$B:$B,"<="&$B6)) -> NA | N6: =IF(COUNTIFS(monthly!F:F,"",monthly!$A:$A,">="&$A6,monthly!$B:$B,"<="&$B6)>0,"NA",AVERAGEIFS(monthly!F:F,monthly!$A:$A,">="&$A6,monthly!$B:$B,"<="&$B6)) -> NA | O6: =IF(COUNTIFS(monthly!G:G,"",monthly!$A:$A,">="&$A6,monthly!$B:$B,"<="&$B6)>0,"NA",AVERAGEIFS(monthly!G:G,monthly!$A:$A,">="&$A6,monthly!$B:$B,"<="&$B6)) -> 10.3 | P6: =IF(COUNTIFS(monthly!H:H,"",monthly!$A:$A,">="&$A6,monthly!$B:$B,"<="&$B6)>0,"NA",AVERAGEIFS(monthly!H:H,monthly!$A:$A,">="&$A6,monthly!$B:$B,"<="&$B6)) -> 8.7 | Q6: =IF(COUNTIFS(monthly!I:I,"",monthly!$A:$A,">="&$A6,monthly!$B:$B,"<="&$B6)>0,"NA",AVERAGEIFS(monthly!I:I,monthly!$A:$A,">="&$A6,monthly!$B:$B,"<="&$B6)) -> 1.6 | R6: =IF(COUNTIFS(monthly!J:J,"",monthly!$A:$A,">="&$A6,monthly!$B:$B,"<="&$B6)>0,"NA",AVERAGEIFS(monthly!J:J,monthly!$A:$A,">="&$A6,monthly!$B:$B,"<="&$B6)) -> NA | S6: =IF(COUNTIFS(monthly!K:K,"",monthly!$A:$A,">="&$A6,monthly!$B:$B,"<="&$B6)>0,"NA",AVERAGEIFS(monthly!K:K,monthly!$A:$A,">="&$A6,monthly!$B:$B,"<="&$B6)) -> NA | T6: =IF(COUNTIFS(monthly!L:L,"",monthly!$A:$A,">="&$A6,monthly!$B:$B,"<="&$B6)>0,"NA",AVERAGEIFS(monthly!L:L,monthly!$A:$A,">="&$A6,monthly!$B:$B,"<="&$B6)) -> 3.9314862 | U6: =IF(COUNTIFS(monthly!M:M,"",monthly!$A:$A,">="&$A6,monthly!$B:$B,"<="&$B6)>0,"NA",AVERAGEIFS(monthly!M:M,monthly!$A:$A,">="&$A6,monthly!$B:$B,"<="&$B6)) -> NA | V6: =IF(COUNTIFS(monthly!N:N,"",monthly!$A:$A,">="&$A6,monthly!$B:$B,"<="&$B6)>0,"NA",AVERAGEIFS(monthly!N:N,monthly!$A:$A,">="&$A6,monthly!$B:$B,"<="&$B6)) -> NA | W6: =IF(COUNTIFS(monthly!O:O,"",monthly!$A:$A,">="&$A6,monthly!$B:$B,"<="&$B6)>0,"NA",AVERAGEIFS(monthly!O:O,monthly!$A:$A,">="&$A6,monthly!$B:$B,"<="&$B6)) -> NA | X6: =IF(COUNTIFS(monthly!P:P,"",monthly!$A:$A,">="&$A6,monthly!$B:$B,"<="&$B6)>0,"NA",AVERAGEIFS(monthly!P:P,monthly!$A:$A,">="&$A6,monthly!$B:$B,"<="&$B6)) -> NA | Y6: =IF(COUNTIFS(monthly!Q:Q,"",monthly!$A:$A,">="&$A6,monthly!$B:$B,"<="&$B6)>0,"NA",AVERAGEIFS(monthly!Q:Q,monthly!$A:$A,">="&$A6,monthly!$B:$B,"<="&$B6)) -> 6.85 | Z6: =IF(COUNTIFS(monthly!R:R,"",monthly!$A:$A,">="&$A6,monthly!$B:$B,"<="&$B6)>0,"NA",AVERAGEIFS(monthly!R:R,monthly!$A:$A,">="&$A6,monthly!$B:$B,"<="&$B6)) -> 6.1753611 | AA6: =IF(COUNTIFS(monthly!S:S,"",monthly!$A:$A,">="&$A6,monthly!$B:$B,"<="&$B6)>0,"NA",AVERAGEIFS(monthly!S:S,monthly!$A:$A,">="&$A6,monthly!$B:$B,"<="&$B6)) -> 0.67463889 | AB6: =IF(COUNTIFS(monthly!T:T,"",monthly!$A:$A,">="&$A6,monthly!$B:$B,"<="&$B6)>0,"NA",AVERAGEIFS(monthly!T:T,monthly!$A:$A,">="&$A6,monthly!$B:$B,"<="&$B6)) -> NA | AC6: =IF(COUNTIFS(monthly!U:U,"",monthly!$A:$A,">="&$A6,monthly!$B:$B,"<="&$B6)>0,"NA",AVERAGEIFS(monthly!U:U,monthly!$A:$A,">="&$A6,monthly!$B:$B,"<="&$B6)) -> NA | AD6: =IF(COUNTIFS(monthly!V:V,"",monthly!$A:$A,">="&$A6,monthly!$B:$B,"<="&$B6)>0,"NA",AVERAGEIFS(monthly!V:V,monthly!$A:$A,">="&$A6,monthly!$B:$B,"<="&$B6)) -> NA | AE6: =IF(COUNTIFS(monthly!W:W,"",monthly!$A:$A,">="&$A6,monthly!$B:$B,"<="&$B6)>0,"NA",AVERAGEIFS(monthly!W:W,monthly!$A:$A,">="&$A6,monthly!$B:$B,"<="&$B6)) -> NA | AF6: =IF(COUNTIFS(monthly!X:X,"",monthly!$A:$A,">="&$A6,monthly!$B:$B,"<="&$B6)>0,"NA",AVERAGEIFS(monthly!X:X,monthly!$A:$A,">="&$A6,monthly!$B:$B,"<="&$B6)) -> NA | AG6: =IF(COUNTIFS(monthly!Y:Y,"",monthly!$A:$A,">="&$A6,monthly!$B:$B,"<="&$B6)>0,"NA",AVERAGEIFS(monthly!Y:Y,monthly!$A:$A,">="&$A6,monthly!$B:$B,"<="&$B6)) -> NA | AH6: =IF(COUNTIFS(monthly!Z:Z,"",monthly!$A:$A,">="&$A6,monthly!$B:$B,"<="&$B6)>0,"NA",AVERAGEIFS(monthly!Z:Z,monthly!$A:$A,">="&$A6,monthly!$B:$B,"<="&$B6)) -> NA
A7: 26024 | B7: 26114 | C7: =IF(ISBLANK(VLOOKUP($A7,quarterly_data,MATCH(C$1,quarterly!$1:$1,FALSE),FALSE)),"NA",VLOOKUP($A7,quarterly_data,MATCH(C$1,quarterly!$1:$1,FALSE),FALSE)) -> 147.05388 | D7: =IF(ISBLANK(VLOOKUP($A7,quarterly_data,MATCH(D$1,quarterly!$1:$1,FALSE),FALSE)),"NA",VLOOKUP($A7,quarterly_data,MATCH(D$1,quarterly!$1:$1,FALSE),FALSE)) -> 54.7 | E7: =IF(ISBLANK(VLOOKUP($A7,quarterly_data,MATCH(E$1,quarterly!$1:$1,FALSE),FALSE)),"NA",VLOOKUP($A7,quarterly_data,MATCH(E$1,quarterly!$1:$1,FALSE),FALSE)) -> 0 | F7: =IF(ISBLANK(VLOOKUP($A7,quarterly_data,MATCH(F$1,quarterly!$1:$1,FALSE),FALSE)),"NA",VLOOKUP($A7,quarterly_data,MATCH(F$1,quarterly!$1:$1,FALSE),FALSE)) -> 0.0776852 | G7: =IF(ISBLANK(VLOOKUP($A7,quarterly_data,MATCH(G$1,quarterly!$1:$1,FALSE),FALSE)),"NA",VLOOKUP($A7,quarterly_data,MATCH(G$1,quarterly!$1:$1,FALSE),FALSE)) -> 5473.059 | H7: =IF(ISBLANK(VLOOKUP($A7,quarterly_data,MATCH(H$1,quarterly!$1:$1,FALSE),FALSE)),"NA",VLOOKUP($A7,quarterly_data,MATCH(H$1,quarterly!$1:$1,FALSE),FALSE)) -> 141684 | I7: =IF(ISBLANK(VLOOKUP($A7,quarterly_data,MATCH(I$1,quarterly!$1:$1,FALSE),FALSE)),"NA",VLOOKUP($A7,quarterly_data,MATCH(I$1,quarterly!$1:$1,FALSE),FALSE)) -> NA | J7: =IF(ISBLANK(VLOOKUP($A7,quarterly_data,MATCH(J$1,quarterly!$1:$1,FALSE),FALSE)),"NA",VLOOKUP($A7,quarterly_data,MATCH(J$1,quarterly!$1:$1,FALSE),FALSE)) -> 7.11 | K7: =IF(COUNTIFS(monthly!C:C,"",monthly!$A:$A,">="&$A7,monthly!$B:$B,"<="&$B7)>0,"NA",AVERAGEIFS(monthly!C:C,monthly!$A:$A,">="&$A7,monthly!$B:$B,"<="&$B7)) -> 99.866667 | L7: =IF(COUNTIFS(monthly!D:D,"",monthly!$A:$A,">="&$A7,monthly!$B:$B,"<="&$B7)>0,"NA",AVERAGEIFS(monthly!D:D,monthly!$A:$A,">="&$A7,monthly!$B:$B,"<="&$B7)) -> 1.1264667 | M7: =IF(COUNTIFS(monthly!E:E,"",monthly!$A:$A,">="&$A7,monthly!$B:$B,"<="&$B7)>0,"NA",AVERAGEIFS(monthly!E:E,monthly!$A:$A,">="&$A7,monthly!$B:$B,"<="&$B7)) -> NA | N7: =IF(COUNTIFS(monthly!F:F,"",monthly!$A:$A,">="&$A7,monthly!$B:$B,"<="&$B7)>0,"NA",AVERAGEIFS(monthly!F:F,monthly!$A:$A,">="&$A7,monthly!$B:$B,"<="&$B7)) -> NA | O7: =IF(COUNTIFS(monthly!G:G,"",monthly!$A:$A,">="&$A7,monthly!$B:$B,"<="&$B7)>0,"NA",AVERAGEIFS(monthly!G:G,monthly!$A:$A,">="&$A7,monthly!$B:$B,"<="&$B7)) -> 10.3 | P7: =IF(COUNTIFS(monthly!H:H,"",monthly!$A:$A,">="&$A7,monthly!$B:$B,"<="&$B7)>0,"NA",AVERAGEIFS(monthly!H:H,monthly!$A:$A,">="&$A7,monthly!$B:$B,"<="&$B7)) -> 8.7 | Q7: =IF(COUNTIFS(monthly!I:I,"",monthly!$A:$A,">="&$A7,monthly!$B:$B,"<="&$B7)>0,"NA",AVERAGEIFS(monthly!I:I,monthly!$A:$A,">="&$A7,monthly!$B:$B,"<="&$B7)) -> 1.6 | R7: =IF(COUNTIFS(monthly!J:J,"",monthly!$A:$A,">="&$A7,monthly!$B:$B,"<="&$B7)>0,"NA",AVERAGEIFS(monthly!J:J,monthly!$A:$A,">="&$A7,monthly!$B:$B,"<="&$B7)) -> NA | S7: =IF(COUNTIFS(monthly!K:K,"",monthly!$A:$A,">="&$A7,monthly!$B:$B,"<="&$B7)>0,"NA",AVERAGEIFS(monthly!K:K,monthly!$A:$A,">="&$A7,monthly!$B:$B,"<="&$B7)) -> NA | T7: =IF(COUNTIFS(monthly!L:L,"",monthly!$A:$A,">="&$A7,monthly!$B:$B,"<="&$B7)>0,"NA",AVERAGEIFS(monthly!L:L,monthly!$A:$A,">="&$A7,monthly!$B:$B,"<="&$B7)) -> 4.5665305 | U7: =IF(COUNTIFS(monthly!M:M,"",monthly!$A:$A,">="&$A7,monthly!$B:$B,"<="&$B7)>0,"NA",AVERAGEIFS(monthly!M:M,monthly!$A:$A,">="&$A7,monthly!$B:$B,"<="&$B7)) -> NA | V7: =IF(COUNTIFS(monthly!N:N,"",monthly!$A:$A,">="&$A7,monthly!$B:$B,"<="&$B7)>0,"NA",AVERAGEIFS(monthly!N:N,monthly!$A:$A,">="&$A7,monthly!$B:$B,"<="&$B7)) -> NA | W7: =IF(COUNTIFS(monthly!O:O,"",monthly!$A:$A,">="&$A7,monthly!$B:$B,"<="&$B7)>0,"NA",AVERAGEIFS(monthly!O:O,monthly!$A:$A,">="&$A7,monthly!$B:$B,"<="&$B7)) -> NA | X7: =IF(COUNTIFS(monthly!P:P,"",monthly!$A:$A,">="&$A7,monthly!$B:$B,"<="&$B7)>0,"NA",AVERAGEIFS(monthly!P:P,monthly!$A:$A,">="&$A7,monthly!$B:$B,"<="&$B7)) -> NA | Y7: =IF(COUNTIFS(monthly!Q:Q,"",monthly!$A:$A,">="&$A7,monthly!$B:$B,"<="&$B7)>0,"NA",AVERAGEIFS(monthly!Q:Q,monthly!$A:$A,">="&$A7,monthly!$B:$B,"<="&$B7)) -> 6.8333333 | Z7: =IF(COUNTIFS(monthly!R:R,"",monthly!$A:$A,">="&$A7,monthly!$B:$B,"<="&$B7)>0,"NA",AVERAGEIFS(monthly!R:R,monthly!$A:$A,">="&$A7,monthly!$B:$B,"<="&$B7)) -> 6.2495274 | AA7: =IF(COUNTIFS(monthly!S:S,"",monthly!$A:$A,">="&$A7,monthly!$B:$B,"<="&$B7)>0,"NA",AVERAGEIFS(monthly!S:S,monthly!$A:$A,">="&$A7,monthly!$B:$B,"<="&$B7)) -> 0.58380592 | AB7: =IF(COUNTIFS(monthly!T:T,"",monthly!$A:$A,">="&$A7,monthly!$B:$B,"<="&$B7)>0,"NA",AVERAGEIFS(monthly!T:T,monthly!$A:$A,">="&$A7,monthly!$B:$B,"<="&$B7)) -> NA | AC7: =IF(COUNTIFS(monthly!U:U,"",monthly!$A:$A,">="&$A7,monthly!$B:$B,"<="&$B7)>0,"NA",AVERAGEIFS(monthly!U:U,monthly!$A:$A,">="&$A7,monthly!$B:$B,"<="&$B7)) -> NA | AD7: =IF(COUNTIFS(monthly!V:V,"",monthly!$A:$A,">="&$A7,monthly!$B:$B,"<="&$B7)>0,"NA",AVERAGEIFS(monthly!V:V,monthly!$A:$A,">="&$A7,monthly!$B:$B,"<="&$B7)) -> NA | AE7: =IF(COUNTIFS(monthly!W:W,"",monthly!$A:$A,">="&$A7,monthly!$B:$B,"<="&$B7)>0,"NA",AVERAGEIFS(monthly!W:W,monthly!$A:$A,">="&$A7,monthly!$B:$B,"<="&$B7)) -> NA | AF7: =IF(COUNTIFS(monthly!X:X,"",monthly!$A:$A,">="&$A7,monthly!$B:$B,"<="&$B7)>0,"NA",AVERAGEIFS(monthly!X:X,monthly!$A:$A,">="&$A7,monthly!$B:$B,"<="&$B7)) -> NA | AG7: =IF(COUNTIFS(monthly!Y:Y,"",monthly!$A:$A,">="&$A7,monthly!$B:$B,"<="&$B7)>0,"NA",AVERAGEIFS(monthly!Y:Y,monthly!$A:$A,">="&$A7,monthly!$B:$B,"<="&$B7)) -> NA | AH7: =IF(COUNTIFS(monthly!Z:Z,"",monthly!$A:$A,">="&$A7,monthly!$B:$B,"<="&$B7)>0,"NA",AVERAGEIFS(monthly!Z:Z,monthly!$A:$A,">="&$A7,monthly!$B:$B,"<="&$B7)) -> NA
A8: 26115 | B8: 26206 | C8: =IF(ISBLANK(VLOOKUP($A8,quarterly_data,MATCH(C$1,quarterly!$1:$1,FALSE),FALSE)),"NA",VLOOKUP($A8,quarterly_data,MATCH(C$1,quarterly!$1:$1,FALSE),FALSE)) -> 146.56491 | D8: =IF(ISBLANK(VLOOKUP($A8,quarterly_data,MATCH(D$1,quarterly!$1:$1,FALSE),FALSE)),"NA",VLOOKUP($A8,quarterly_data,MATCH(D$1,quarterly!$1:$1,FALSE),FALSE)) -> 55.5 | E8: =IF(ISBLANK(VLOOKUP($A8,quarterly_data,MATCH(E$1,quarterly!$1:$1,FALSE),FALSE)),"NA",VLOOKUP($A8,quarterly_data,MATCH(E$1,quarterly!$1:$1,FALSE),FALSE)) -> 0.337344 | F8: =IF(ISBLANK(VLOOKUP($A8,quarterly_data,MATCH(F$1,quarterly!$1:$1,FALSE),FALSE)),"NA",VLOOKUP($A8,quarterly_data,MATCH(F$1,quarterly!$1:$1,FALSE),FALSE)) -> 0.0893124 | G8: =IF(ISBLANK(VLOOKUP($A8,quarterly_data,MATCH(G$1,quarterly!$1:$1,FALSE),FALSE)),"NA",VLOOKUP($A8,quarterly_data,MATCH(G$1,quarterly!$1:$1,FALSE),FALSE)) -> 5518.072 | H8: =IF(ISBLANK(VLOOKUP($A8,quarterly_data,MATCH(H$1,quarterly!$1:$1,FALSE),FALSE)),"NA",VLOOKUP($A8,quarterly_data,MATCH(H$1,quarterly!$1:$1,FALSE),FALSE)) -> 146097 | I8: =IF(ISBLANK(VLOOKUP($A8,quarterly_data,MATCH(I$1,quarterly!$1:$1,FALSE),FALSE)),"NA",VLOOKUP($A8,quarterly_data,MATCH(I$1,quarterly!$1:$1,FALSE),FALSE)) -> NA | J8: =IF(ISBLANK(VLOOKUP($A8,quarterly_data,MATCH(J$1,quarterly!$1:$1,FALSE),FALSE)),"NA",VLOOKUP($A8,quarterly_data,MATCH(J$1,quarterly!$1:$1,FALSE),FALSE)) -> 7.27 | K8: =IF(COUNTIFS(monthly!C:C,"",monthly!$A:$A,">="&$A8,monthly!$B:$B,"<="&$B8)>0,"NA",AVERAGEIFS(monthly!C:C,monthly!$A:$A,">="&$A8,monthly!$B:$B,"<="&$B8)) -> 99.6 | L8: =IF(COUNTIFS(monthly!D:D,"",monthly!$A:$A,">="&$A8,monthly!$B:$B,"<="&$B8)>0,"NA",AVERAGEIFS(monthly!D:D,monthly!$A:$A,">="&$A8,monthly!$B:$B,"<="&$B8)) -> 1.1440333 | M8: =IF(COUNTIFS(monthly!E:E,"",monthly!$A:$A,">="&$A8,monthly!$B:$B,"<="&$B8)>0,"NA",AVERAGEIFS(monthly!E:E,monthly!$A:$A,">="&$A8,monthly!$B:$B,"<="&$B8)) -> NA | N8: =IF(COUNTIFS(monthly!F:F,"",monthly!$A:$A,">="&$A8,monthly!$B:$B,"<="&$B8)>0,"NA",AVERAGEIFS(monthly!F:F,monthly!$A:$A,">="&$A8,monthly!$B:$B,"<="&$B8)) -> NA | O8: =IF(COUNTIFS(monthly!G:G,"",monthly!$A:$A,">="&$A8,monthly!$B:$B,"<="&$B8)>0,"NA",AVERAGEIFS(monthly!G:G,monthly!$A:$A,">="&$A8,monthly!$B:$B,"<="&$B8)) -> 10.3 | P8: =IF(COUNTIFS(monthly!H:H,"",monthly!$A:$A,">="&$A8,monthly!$B:$B,"<="&$B8)>0,"NA",AVERAGEIFS(monthly!H:H,monthly!$A:$A,">="&$A8,monthly!$B:$B,"<="&$B8)) -> 8.7 | Q8: =IF(COUNTIFS(monthly!I:I,"",monthly!$A:$A,">="&$A8,monthly!$B:$B,"<="&$B8)>0,"NA",AVERAGEIFS(monthly!I:I,monthly!$A:$A,">="&$A8,monthly!$B:$B,"<="&$B8)) -> 1.7 | R8: =IF(COUNTIFS(monthly!J:J,"",monthly!$A:$A,">="&$A8,monthly!$B:$B,"<="&$B8)>0,"NA",AVERAGEIFS(monthly!J:J,monthly!$A:$A,">="&$A8,monthly!$B:$B,"<="&$B8)) -> NA | S8: =IF(COUNTIFS(monthly!K:K,"",monthly!$A:$A,">="&$A8,monthly!$B:$B,"<="&$B8)>0,"NA",AVERAGEIFS(monthly!K:K,monthly!$A:$A,">="&$A8,monthly!$B:$B,"<="&$B8)) -> NA | T8: =IF(COUNTIFS(monthly!L:L,"",monthly!$A:$A,">="&$A8,monthly!$B:$B,"<="&$B8)>0,"NA",AVERAGEIFS(monthly!L:L,monthly!$A:$A,">="&$A8,monthly!$B:$B,"<="&$B8)) -> 5.4763835 | U8: =IF(COUNTIFS(monthly!M:M,"",monthly!$A:$A,">="&$A8,monthly!$B:$B,"<="&$B8)>0,"NA",AVERAGEIFS(monthly!M:M,monthly!$A:$A,">="&$A8,monthly!$B:$B,"<="&$B8)) -> NA | V8: =IF(COUNTIFS(monthly!N:N,"",monthly!$A:$A,">="&$A8,monthly!$B:$B,"<="&$B8)>0,"NA",AVERAGEIFS(monthly!N:N,monthly!$A:$A,">="&$A8,monthly!$B:$B,"<="&$B8)) -> NA | W8: =IF(COUNTIFS(monthly!O:O,"",monthly!$A:$A,">="&$A8,monthly!$B:$B,"<="&$B8)>0,"NA",AVERAGEIFS(monthly!O:O,monthly!$A:$A,">="&$A8,monthly!$B:$B,"<="&$B8)) -> NA | X8: =IF(COUNTIFS(monthly!P:P,"",monthly!$A:$A,">="&$A8,monthly!$B:$B,"<="&$B8)>0,"NA",AVERAGEIFS(monthly!P:P,monthly!$A:$A,">="&$A8,monthly!$B:$B,"<="&$B8)) -> NA | Y8: =IF(COUNTIFS(monthly!Q:Q,"",monthly!$A:$A,">="&$A8,monthly!$B:$B,"<="&$B8)>0,"NA",AVERAGEIFS(monthly!Q:Q,monthly!$A:$A,">="&$A8,monthly!$B:$B,"<="&$B8)) -> 6.8033333 | Z8: =IF(COUNTIFS(monthly!R:R,"",monthly!$A:$A,">="&$A8,monthly!$B:$B,"<="&$B8)>0,"NA",AVERAGEIFS(monthly!R:R,monthly!$A:$A,">="&$A8,monthly!$B:$B,"<="&$B8)) -> 6.483925 | AA8: =IF(COUNTIFS(monthly!S:S,"",monthly!$A:$A,">="&$A8,monthly!$B:$B,"<="&$B8)>0,"NA",AVERAGEIFS(monthly!S:S,monthly!$A:$A,">="&$A8,monthly!$B:$B,"<="&$B8)) -> 0.31940837 | AB8: =IF(COUNTIFS(monthly!T:T,"",monthly!$A:$A,">="&$A8,monthly!$B:$B,"<="&$B8)>0,"NA",AVERAGEIFS(monthly!T:T,monthly!$A:$A,">="&$A8,monthly!$B:$B,"<="&$B8)) -> NA | AC8: =IF(COUNTIFS(monthly!U:U,"",monthly!$A:$A,">="&$A8,monthly!$B:$B,"<="&$B8)>0,"NA",AVERAGEIFS(monthly!U:U,monthly!$A:$A,">="&$A8,monthly!$B:$B,"<="&$B8)) -> NA | AD8: =IF(COUNTIFS(monthly!V:V,"",monthly!$A:$A,">="&$A8,monthly!$B:$B,"<="&$B8)>0,"NA",AVERAGEIFS(monthly!V:V,monthly!$A:$A,">="&$A8,monthly!$B:$B,"<="&$B8)) -> NA | AE8: =IF(COUNTIFS(monthly!W:W,"",monthly!$A:$A,">="&$A8,monthly!$B:$B,"<="&$B8)>0,"NA",AVERAGEIFS(monthly!W:W,monthly!$A:$A,">="&$A8,monthly!$B:$B,"<="&$B8)) -> NA | AF8: =IF(COUNTIFS(monthly!X:X,"",monthly!$A:$A,">="&$A8,monthly!$B:$B,"<="&$B8)>0,"NA",AVERAGEIFS(monthly!X:X,monthly!$A:$A,">="&$A8,monthly!$B:$B,"<="&$B8)) -> NA | AG8: =IF(COUNTIFS(monthly!Y:Y,"",monthly!$A:$A,">="&$A8,monthly!$B:$B,"<="&$B8)>0,"NA",AVERAGEIFS(monthly!Y:Y,monthly!$A:$A,">="&$A8,monthly!$B:$B,"<="&$B8)) -> NA | AH8: =IF(COUNTIFS(monthly!Z:Z,"",monthly!$A:$A,">="&$A8,monthly!$B:$B,"<="&$B8)>0,"NA",AVERAGEIFS(monthly!Z:Z,monthly!$A:$A,">="&$A8,monthly!$B:$B,"<="&$B8)) -> NA
A9: 26207 | B9: 26297 | C9: =IF(ISBLANK(VLOOKUP($A9,quarterly_data,MATCH(C$1,quarterly!$1:$1,FALSE),FALSE)),"NA",VLOOKUP($A9,quarterly_data,MATCH(C$1,quarterly!$1:$1,FALSE),FALSE)) -> 147.06334 | D9: =IF(ISBLANK(VLOOKUP($A9,quarterly_data,MATCH(D$1,quarterly!$1:$1,FALSE),FALSE)),"NA",VLOOKUP($A9,quarterly_data,MATCH(D$1,quarterly!$1:$1,FALSE),FALSE)) -> 48.6 | E9: =IF(ISBLANK(VLOOKUP($A9,quarterly_data,MATCH(E$1,quarterly!$1:$1,FALSE),FALSE)),"NA",VLOOKUP($A9,quarterly_data,MATCH(E$1,quarterly!$1:$1,FALSE),FALSE)) -> 0.449169 | F9: =IF(ISBLANK(VLOOKUP($A9,quarterly_data,MATCH(F$1,quarterly!$1:$1,FALSE),FALSE)),"NA",VLOOKUP($A9,quarterly_data,MATCH(F$1,quarterly!$1:$1,FALSE),FALSE)) -> 0.1235682 | G9: =IF(ISBLANK(VLOOKUP($A9,quarterly_data,MATCH(G$1,quarterly!$1:$1,FALSE),FALSE)),"NA",VLOOKUP($A9,quarterly_data,MATCH(G$1,quarterly!$1:$1,FALSE),FALSE)) -> 5531.032 | H9: =IF(ISBLANK(VLOOKUP($A9,quarterly_data,MATCH(H$1,quarterly!$1:$1,FALSE),FALSE)),"NA",VLOOKUP($A9,quarterly_data,MATCH(H$1,quarterly!$1:$1,FALSE),FALSE)) -> 145625 | I9: =IF(ISBLANK(VLOOKUP($A9,quarterly_data,MATCH(I$1,quarterly!$1:$1,FALSE),FALSE)),"NA",VLOOKUP($A9,quarterly_data,MATCH(I$1,quarterly!$1:$1,FALSE),FALSE)) -> NA | J9: =IF(ISBLANK(VLOOKUP($A9,quarterly_data,MATCH(J$1,quarterly!$1:$1,FALSE),FALSE)),"NA",VLOOKUP($A9,quarterly_data,MATCH(J$1,quarterly!$1:$1,FALSE),FALSE)) -> 7.42 | K9: =IF(COUNTIFS(monthly!C:C,"",monthly!$A:$A,">="&$A9,monthly!$B:$B,"<="&$B9)>0,"NA",AVERAGEIFS(monthly!C:C,monthly!$A:$A,">="&$A9,monthly!$B:$B,"<="&$B9)) -> 99.35 | L9: =IF(COUNTIFS(monthly!D:D,"",monthly!$A:$A,">="&$A9,monthly!$B:$B,"<="&$B9)>0,"NA",AVERAGEIFS(monthly!D:D,monthly!$A:$A,">="&$A9,monthly!$B:$B,"<="&$B9)) -> 1.16145 | M9: =IF(COUNTIFS(monthly!E:E,"",monthly!$A:$A,">="&$A9,monthly!$B:$B,"<="&$B9)>0,"NA",AVERAGEIFS(monthly!E:E,monthly!$A:$A,">="&$A9,monthly!$B:$B,"<="&$B9)) -> NA | N9: =IF(COUNTIFS(monthly!F:F,"",monthly!$A:$A,">="&$A9,monthly!$B:$B,"<="&$B9)>0,"NA",AVERAGEIFS(monthly!F:F,monthly!$A:$A,">="&$A9,monthly!$B:$B,"<="&$B9)) -> NA | O9: =IF(COUNTIFS(monthly!G:G,"",monthly!$A:$A,">="&$A9,monthly!$B:$B,"<="&$B9)>0,"NA",AVERAGEIFS(monthly!G:G,monthly!$A:$A,">="&$A9,monthly!$B:$B,"<="&$B9)) -> 10.3 | P9: =IF(COUNTIFS(monthly!H:H,"",monthly!$A:$A,">="&$A9,monthly!$B:$B,"<="&$B9)>0,"NA",AVERAGEIFS(monthly!H:H,monthly!$A:$A,">="&$A9,monthly!$B:$B,"<="&$B9)) -> 8.7 | Q9: =IF(COUNTIFS(monthly!I:I,"",monthly!$A:$A,">="&$A9,monthly!$B:$B,"<="&$B9)>0,"NA",AVERAGEIFS(monthly!I:I,monthly!$A:$A,">="&$A9,monthly!$B:$B,"<="&$B9)) -> 1.7 | R9: =IF(COUNTIFS(monthly!J:J,"",monthly!$A:$A,">="&$A9,monthly!$B:$B,"<="&$B9)>0,"NA",AVERAGEIFS(monthly!J:J,monthly!$A:$A,">="&$A9,monthly!$B:$B,"<="&$B9)) -> NA | S9: =IF(COUNTIFS(monthly!K:K,"",monthly!$A:$A,">="&$A9,monthly!$B:$B,"<="&$B9)>0,"NA",AVERAGEIFS(monthly!K:K,monthly!$A:$A,">="&$A9,monthly!$B:$B,"<="&$B9)) -> NA | T9: =IF(COUNTIFS(monthly!L:L,"",monthly!$A:$A,">="&$A9,monthly!$B:$B,"<="&$B9)>0,"NA",AVERAGEIFS(monthly!L:L,monthly!$A:$A,">="&$A9,monthly!$B:$B,"<="&$B9)) -> 5.0548441 | U9: =IF(COUNTIFS(monthly!M:M,"",monthly!$A:$A,">="&$A9,monthly!$B:$B,"<="&$B9)>0,"NA",AVERAGEIFS(monthly!M:M,monthly!$A:$A,">="&$A9,monthly!$B:$B,"<="&$B9)) -> NA | V9: =IF(COUNTIFS(monthly!N:N,"",monthly!$A:$A,">="&$A9,monthly!$B:$B,"<="&$B9)>0,"NA",AVERAGEIFS(monthly!N:N,monthly!$A:$A,">="&$A9,monthly!$B:$B,"<="&$B9)) -> NA | W9: =IF(COUNTIFS(monthly!O:O,"",monthly!$A:$A,">="&$A9,monthly!$B:$B,"<="&$B9)>0,"NA",AVERAGEIFS(monthly!O:O,monthly!$A:$A,">="&$A9,monthly!$B:$B,"<="&$B9)) -> NA | X9: =IF(COUNTIFS(monthly!P:P,"",monthly!$A:$A,">="&$A9,monthly!$B:$B,"<="&$B9)>0,"NA",AVERAGEIFS(monthly!P:P,monthly!$A:$A,">="&$A9,monthly!$B:$B,"<="&$B9)) -> NA | Y9: =IF(COUNTIFS(monthly!Q:Q,"",monthly!$A:$A,">="&$A9,monthly!$B:$B,"<="&$B9)>0,"NA",AVERAGEIFS(monthly!Q:Q,monthly!$A:$A,">="&$A9,monthly!$B:$B,"<="&$B9)) -> 6.48 | Z9: =IF(COUNTIFS(monthly!R:R,"",monthly!$A:$A,">="&$A9,monthly!$B:$B,"<="&$B9)>0,"NA",AVERAGEIFS(monthly!R:R,monthly!$A:$A,">="&$A9,monthly!$B:$B,"<="&$B9)) -> 5.8678947 | AA9: =IF(COUNTIFS(monthly!S:S,"",monthly!$A:$A,">="&$A9,monthly!$B:$B,"<="&$B9)>0,"NA",AVERAGEIFS(monthly!S:S,monthly!$A:$A,">="&$A9,monthly!$B:$B,"<="&$B9)) -> 0.61210526 | AB9: =IF(COUNTIFS(monthly!T:T,"",monthly!$A:$A,">="&$A9,monthly!$B:$B,"<="&$B9)>0,"NA",AVERAGEIFS(monthly!T:T,monthly!$A:$A,">="&$A9,monthly!$B:$B,"<="&$B9)) -> NA | AC9: =IF(COUNTIFS(monthly!U:U,"",monthly!$A:$A,">="&$A9,monthly!$B:$B,"<="&$B9)>0,"NA",AVERAGEIFS(monthly!U:U,monthly!$A:$A,">="&$A9,monthly!$B:$B,"<="&$B9)) -> NA | AD9: =IF(COUNTIFS(monthly!V:V,"",monthly!$A:$A,">="&$A9,monthly!$B:$B,"<="&$B9)>0,"NA",AVERAGEIFS(monthly!V:V,monthly!$A:$A,">="&$A9,monthly!$B:$B,"<="&$B9)) -> NA | AE9: =IF(COUNTIFS(monthly!W:W,"",monthly!$A:$A,">="&$A9,monthly!$B:$B,"<="&$B9)>0,"NA",AVERAGEIFS(monthly!W:W,monthly!$A:$A,">="&$A9,monthly!$B:$B,"<="&$B9)) -> NA | AF9: =IF(COUNTIFS(monthly!X:X,"",monthly!$A:$A,">="&$A9,monthly!$B:$B,"<="&$B9)>0,"NA",AVERAGEIFS(monthly!X:X,monthly!$A:$A,">="&$A9,monthly!$B:$B,"<="&$B9)) -> NA | AG9: =IF(COUNTIFS(monthly!Y:Y,"",monthly!$A:$A,">="&$A9,monthly!$B:$B,"<="&$B9)>0,"NA",AVERAGEIFS(monthly!Y:Y,monthly!$A:$A,">="&$A9,monthly!$B:$B,"<="&$B9)) -> NA | AH9: =IF(COUNTIFS(monthly!Z:Z,"",monthly!$A:$A,">="&$A9,monthly!$B:$B,"<="&$B9)>0,"NA",AVERAGEIFS(monthly!Z:Z,monthly!$A:$A,">="&$A9,monthly!$B:$B,"<="&$B9)) -> NA
A10: 26299 | B10: 26388 | C10: =IF(ISBLANK(VLOOKUP($A10,quarterly_data,MATCH(C$1,quarterly!$1:$1,FALSE),FALSE)),"NA",VLOOKUP($A10,quarterly_data,MATCH(C$1,quarterly!$1:$1,FALSE),FALSE)) -> 145.50562 | D10: =IF(ISBLANK(VLOOKUP($A10,quarterly_data,MATCH(D$1,quarterly!$1:$1,FALSE),FALSE)),"NA",VLOOKUP($A10,quarterly_data,MATCH(D$1,quarterly!$1:$1,FALSE),FALSE)) -> 51.8 | E10: =IF(ISBLANK(VLOOKUP($A10,quarterly_data,MATCH(E$1,quarterly!$1:$1,FALSE),FALSE)),"NA",VLOOKUP($A10,quarterly_data,MATCH(E$1,quarterly!$1:$1,FALSE),FALSE)) -> 0.304909 | F10: =IF(ISBLANK(VLOOKUP($A10,quarterly_data,MATCH(F$1,quarterly!$1:$1,FALSE),FALSE)),"NA",VLOOKUP($A10,quarterly_data,MATCH(F$1,quarterly!$1:$1,FALSE),FALSE)) -> 0.1171435 | G10: =IF(ISBLANK(VLOOKUP($A10,quarterly_data,MATCH(G$1,quarterly!$1:$1,FALSE),FALSE)),"NA",VLOOKUP($A10,quarterly_data,MATCH(G$1,quarterly!$1:$1,FALSE),FALSE)) -> 5632.649 | H10: =IF(ISBLANK(VLOOKUP($A10,quarterly_data,MATCH(H$1,quarterly!$1:$1,FALSE),FALSE)),"NA",VLOOKUP($A10,quarterly_data,MATCH(H$1,quarterly!$1:$1,FALSE),FALSE)) -> 143900 | I10: =IF(ISBLANK(VLOOKUP($A10,quarterly_data,MATCH(I$1,quarterly!$1:$1,FALSE),FALSE)),"NA",VLOOKUP($A10,quarterly_data,MATCH(I$1,quarterly!$1:$1,FALSE),FALSE)) -> NA | J10: =IF(ISBLANK(VLOOKUP($A10,quarterly_data,MATCH(J$1,quarterly!$1:$1,FALSE),FALSE)),"NA",VLOOKUP($A10,quarterly_data,MATCH(J$1,quarterly!$1:$1,FALSE),FALSE)) -> 7.5 | K10: =IF(COUNTIFS(monthly!C:C,"",monthly!$A:$A,">="&$A10,monthly!$B:$B,"<="&$B10)>0,"NA",AVERAGEIFS(monthly!C:C,monthly!$A:$A,">="&$A10,monthly!$B:$B,"<="&$B10)) -> 98.45 | L10: =IF(COUNTIFS(monthly!D:D,"",monthly!$A:$A,">="&$A10,monthly!$B:$B,"<="&$B10)>0,"NA",AVERAGEIFS(monthly!D:D,monthly!$A:$A,">="&$A10,monthly!$B:$B,"<="&$B10)) -> 1.191 | M10: =IF(COUNTIFS(monthly!E:E,"",monthly!$A:$A,">="&$A10,monthly!$B:$B,"<="&$B10)>0,"NA",AVERAGEIFS(monthly!E:E,monthly!$A:$A,">="&$A10,monthly!$B:$B,"<="&$B10)) -> NA | N10: =IF(COUNTIFS(monthly!F:F,"",monthly!$A:$A,">="&$A10,monthly!$B:$B,"<="&$B10)>0,"NA",AVERAGEIFS(monthly!F:F,monthly!$A:$A,">="&$A10,monthly!$B:$B,"<="&$B10)) -> NA | O10: =IF(COUNTIFS(monthly!G:G,"",monthly!$A:$A,">="&$A10,monthly!$B:$B,"<="&$B10)>0,"NA",AVERAGEIFS(monthly!G:G,monthly!$A:$A,">="&$A10,monthly!$B:$B,"<="&$B10)) -> 10.3 | P10: =IF(COUNTIFS(monthly!H:H,"",monthly!$A:$A,">="&$A10,monthly!$B:$B,"<="&$B10)>0,"NA",AVERAGEIFS(monthly!H:H,monthly!$A:$A,">="&$A10,monthly!$B:$B,"<="&$B10)) -> 9.6 | Q10: =IF(COUNTIFS(monthly!I:I,"",monthly!$A:$A,">="&$A10,monthly!$B:$B,"<="&$B10)>0,"NA",AVERAGEIFS(monthly!I:I,monthly!$A:$A,">="&$A10,monthly!$B:$B,"<="&$B10)) -> 1.8 | R10: =IF(COUNTIFS(monthly!J:J,"",monthly!$A:$A,">="&$A10,monthly!$B:$B,"<="&$B10)>0,"NA",AVERAGEIFS(monthly!J:J,monthly!$A:$A,">="&$A10,monthly!$B:$B,"<="&$B10)) -> NA | S10: =IF(COUNTIFS(monthly!K:K,"",monthly!$A:$A,">="&$A10,monthly!$B:$B,"<="&$B10)>0,"NA",AVERAGEIFS(monthly!K:K,monthly!$A:$A,">="&$A10,monthly!$B:$B,"<="&$B10)) -> NA | T10: =IF(COUNTIFS(monthly!L:L,"",monthly!$A:$A,">="&$A10,monthly!$B:$B,"<="&$B10)>0,"NA",AVERAGEIFS(monthly!L:L,monthly!$A:$A,">="&$A10,monthly!$B:$B,"<="&$B10)) -> 3.4006618 | U10: =IF(COUNTIFS(monthly!M:M,"",monthly!$A:$A,">="&$A10,monthly!$B:$B,"<="&$B10)>0,"NA",AVERAGEIFS(monthly!M:M,monthly!$A:$A,">="&$A10,monthly!$B:$B,"<="&$B10)) -> NA | V10: =IF(COUNTIFS(monthly!N:N,"",monthly!$A:$A,">="&$A10,monthly!$B:$B,"<="&$B10)>0,"NA",AVERAGEIFS(monthly!N:N,monthly!$A:$A,">="&$A10,monthly!$B:$B,"<="&$B10)) -> NA | W10: =IF(COUNTIFS(monthly!O:O,"",monthly!$A:$A,">="&$A10,monthly!$B:$B,"<="&$B10)>0,"NA",AVERAGEIFS(monthly!O:O,monthly!$A:$A,">="&$A10,monthly!$B:$B,"<="&$B10)) -> NA | X10: =IF(COUNTIFS(monthly!P:P,"",monthly!$A:$A,">="&$A10,monthly!$B:$B,"<="&$B10)>0,"NA",AVERAGEIFS(monthly!P:P,monthly!$A:$A,">="&$A10,monthly!$B:$B,"<="&$B10)) -> NA | Y10: =IF(COUNTIFS(monthly!Q:Q,"",monthly!$A:$A,">="&$A10,monthly!$B:$B,"<="&$B10)>0,"NA",AVERAGEIFS(monthly!Q:Q,monthly!$A:$A,">="&$A10,monthly!$B:$B,"<="&$B10)) -> 5.99 | Z10: =IF(COUNTIFS(monthly!R:R,"",monthly!$A:$A,">="&$A10,monthly!$B:$B,"<="&$B10)>0,"NA",AVERAGEIFS(monthly!R:R,monthly!$A:$A,">="&$A10,monthly!$B:$B,"<="&$B10)) -> 6.0143095 | AA10: =IF(COUNTIFS(monthly!S:S,"",monthly!$A:$A,">="&$A10,monthly!$B:$B,"<="&$B10)>0,"NA",AVERAGEIFS(monthly!S:S,monthly!$A:$A,">="&$A10,monthly!$B:$B,"<="&$B10)) -> -0.024309524 | AB10: =IF(COUNTIFS(monthly!T:T,"",monthly!$A:$A,">="&$A10,monthly!$B:$B,"<="&$B10)>0,"NA",AVERAGEIFS(monthly!T:T,monthly!$A:$A,">="&$A10,monthly!$B:$B,"<="&$B10)) -> NA | AC10: =IF(COUNTIFS(monthly!U:U,"",monthly!$A:$A,">="&$A10,monthly!$B:$B,"<="&$B10)>0,"NA",AVERAGEIFS(monthly!U:U,monthly!$A:$A,">="&$A10,monthly!$B:$B,"<="&$B10)) -> NA | AD10: =IF(COUNTIFS(monthly!V:V,"",monthly!$A:$A,">="&$A10,monthly!$B:$B,"<="&$B10)>0,"NA",AVERAGEIFS(monthly!V:V,monthly!$A:$A,">="&$A10,monthly!$B:$B,"<="&$B10)) -> NA | AE10: =IF(COUNTIFS(monthly!W:W,"",monthly!$A:$A,">="&$A10,monthly!$B:$B,"<="&$B10)>0,"NA",AVERAGEIFS(monthly!W:W,monthly!$A:$A,">="&$A10,monthly!$B:$B,"<="&$B10)) -> NA | AF10: =IF(COUNTIFS(monthly!X:X,"",monthly!$A:$A,">="&$A10,monthly!$B:$B,"<="&$B10)>0,"NA",AVERAGEIFS(monthly!X:X,monthly!$A:$A,">="&$A10,monthly!$B:$B,"<="&$B10)) -> NA | AG10: =IF(COUNTIFS(monthly!Y:Y,"",monthly!$A:$A,">="&$A10,monthly!$B:$B,"<="&$B10)>0,"NA",AVERAGEIFS(monthly!Y:Y,monthly!$A:$A,">="&$A10,monthly!$B:$B,"<="&$B10)) -> NA | AH10: =IF(COUNTIFS(monthly!Z:Z,"",monthly!$A:$A,">="&$A10,monthly!$B:$B,"<="&$B10)>0,"NA",AVERAGEIFS(monthly!Z:Z,monthly!$A:$A,">="&$A10,monthly!$B:$B,"<="&$B10)) -> NA
A11: 26390 | B11: 26480 | C11: =IF(ISBLANK(VLOOKUP($A11,quarterly_data,MATCH(C$1,quarterly!$1:$1,FALSE),FALSE)),"NA",VLOOKUP($A11,quarterly_data,MATCH(C$1,quarterly!$1:$1,FALSE),FALSE)) -> 144.61215 | D11: =IF(ISBLANK(VLOOKUP($A11,quarterly_data,MATCH(D$1,quarterly!$1:$1,FALSE),FALSE)),"NA",VLOOKUP($A11,quarterly_data,MATCH(D$1,quarterly!$1:$1,FALSE),FALSE)) -> 53.9 | E11: =IF(ISBLANK(VLOOKUP($A11,quarterly_data,MATCH(E$1,quarterly!$1:$1,FALSE),FALSE)),"NA",VLOOKUP($A11,quarterly_data,MATCH(E$1,quarterly!$1:$1,FALSE),FALSE)) -> 0 | F11: =IF(ISBLANK(VLOOKUP($A11,quarterly_data,MATCH(F$1,quarterly!$1:$1,FALSE),FALSE)),"NA",VLOOKUP($A11,quarterly_data,MATCH(F$1,quarterly!$1:$1,FALSE),FALSE)) -> 0.0454632 | G11: =IF(ISBLANK(VLOOKUP($A11,quarterly_data,MATCH(G$1,quarterly!$1:$1,FALSE),FALSE)),"NA",VLOOKUP($A11,quarterly_data,MATCH(G$1,quarterly!$1:$1,FALSE),FALSE)) -> 5760.47 | H11: =IF(ISBLANK(VLOOKUP($A11,quarterly_data,MATCH(H$1,quarterly!$1:$1,FALSE),FALSE)),"NA",VLOOKUP($A11,quarterly_data,MATCH(H$1,quarterly!$1:$1,FALSE),FALSE)) -> 147105 | I11: =IF(ISBLANK(VLOOKUP($A11,quarterly_data,MATCH(I$1,quarterly!$1:$1,FALSE),FALSE)),"NA",VLOOKUP($A11,quarterly_data,MATCH(I$1,quarterly!$1:$1,FALSE),FALSE)) -> NA | J11: =IF(ISBLANK(VLOOKUP($A11,quarterly_data,MATCH(J$1,quarterly!$1:$1,FALSE),FALSE)),"NA",VLOOKUP($A11,quarterly_data,MATCH(J$1,quarterly!$1:$1,FALSE),FALSE)) -> 7.58 | K11: =IF(COUNTIFS(monthly!C:C,"",monthly!$A:$A,">="&$A11,monthly!$B:$B,"<="&$B11)>0,"NA",AVERAGEIFS(monthly!C:C,monthly!$A:$A,">="&$A11,monthly!$B:$B,"<="&$B11)) -> 98.1 | L11: =IF(COUNTIFS(monthly!D:D,"",monthly!$A:$A,">="&$A11,monthly!$B:$B,"<="&$B11)>0,"NA",AVERAGEIFS(monthly!D:D,monthly!$A:$A,">="&$A11,monthly!$B:$B,"<="&$B11)) -> 1.191 | M11: =IF(COUNTIFS(monthly!E:E,"",monthly!$A:$A,">="&$A11,monthly!$B:$B,"<="&$B11)>0,"NA",AVERAGEIFS(monthly!E:E,monthly!$A:$A,">="&$A11,monthly!$B:$B,"<="&$B11)) -> NA | N11: =IF(COUNTIFS(monthly!F:F,"",monthly!$A:$A,">="&$A11,monthly!$B:$B,"<="&$B11)>0,"NA",AVERAGEIFS(monthly!F:F,monthly!$A:$A,">="&$A11,monthly!$B:$B,"<="&$B11)) -> NA | O11: =IF(COUNTIFS(monthly!G:G,"",monthly!$A:$A,">="&$A11,monthly!$B:$B,"<="&$B11)>0,"NA",AVERAGEIFS(monthly!G:G,monthly!$A:$A,">="&$A11,monthly!$B:$B,"<="&$B11)) -> 10.3 | P11: =IF(COUNTIFS(monthly!H:H,"",monthly!$A:$A,">="&$A11,monthly!$B:$B,"<="&$B11)>0,"NA",AVERAGEIFS(monthly!H:H,monthly!$A:$A,">="&$A11,monthly!$B:$B,"<="&$B11)) -> 9.6 | Q11: =IF(COUNTIFS(monthly!I:I,"",monthly!$A:$A,">="&$A11,monthly!$B:$B,"<="&$B11)>0,"NA",AVERAGEIFS(monthly!I:I,monthly!$A:$A,">="&$A11,monthly!$B:$B,"<="&$B11)) -> 1.8 | R11: =IF(COUNTIFS(monthly!J:J,"",monthly!$A:$A,">="&$A11,monthly!$B:$B,"<="&$B11)>0,"NA",AVERAGEIFS(monthly!J:J,monthly!$A:$A,">="&$A11,monthly!$B:$B,"<="&$B11)) -> NA | S11: =IF(COUNTIFS(monthly!K:K,"",monthly!$A:$A,">="&$A11,monthly!$B:$B,"<="&$B11)>0,"NA",AVERAGEIFS(monthly!K:K,monthly!$A:$A,">="&$A11,monthly!$B:$B,"<="&$B11)) -> NA | T11: =IF(COUNTIFS(monthly!L:L,"",monthly!$A:$A,">="&$A11,monthly!$B:$B,"<="&$B11)>0,"NA",AVERAGEIFS(monthly!L:L,monthly!$A:$A,">="&$A11,monthly!$B:$B,"<="&$B11)) -> 4.3017814 | U11: =IF(COUNTIFS(monthly!M:M,"",monthly!$A:$A,">="&$A11,monthly!$B:$B,"<="&$B11)>0,"NA",AVERAGEIFS(monthly!M:M,monthly!$A:$A,">="&$A11,monthly!$B:$B,"<="&$B11)) -> NA | V11: =IF(COUNTIFS(monthly!N:N,"",monthly!$A:$A,">="&$A11,monthly!$B:$B,"<="&$B11)>0,"NA",AVERAGEIFS(monthly!N:N,monthly!$A:$A,">="&$A11,monthly!$B:$B,"<="&$B11)) -> NA | W11: =IF(COUNTIFS(monthly!O:O,"",monthly!$A:$A,">="&$A11,monthly!$B:$B,"<="&$B11)>0,"NA",AVERAGEIFS(monthly!O:O,monthly!$A:$A,">="&$A11,monthly!$B:$B,"<="&$B11)) -> NA | X11: =IF(COUNTIFS(monthly!P:P,"",monthly!$A:$A,">="&$A11,monthly!$B:$B,"<="&$B11)>0,"NA",AVERAGEIFS(monthly!P:P,monthly!$A:$A,">="&$A11,monthly!$B:$B,"<="&$B11)) -> NA | Y11: =IF(COUNTIFS(monthly!Q:Q,"",monthly!$A:$A,">="&$A11,monthly!$B:$B,"<="&$B11)>0,"NA",AVERAGEIFS(monthly!Q:Q,monthly!$A:$A,">="&$A11,monthly!$B:$B,"<="&$B11)) -> 5.85 | Z11: =IF(COUNTIFS(monthly!R:R,"",monthly!$A:$A,">="&$A11,monthly!$B:$B,"<="&$B11)>0,"NA",AVERAGEIFS(monthly!R:R,monthly!$A:$A,">="&$A11,monthly!$B:$B,"<="&$B11)) -> 6.1425606 | AA11: =IF(COUNTIFS(monthly!S:S,"",monthly!$A:$A,">="&$A11,monthly!$B:$B,"<="&$B11)>0,"NA",AVERAGEIFS(monthly!S:S,monthly!$A:$A,">="&$A11,monthly!$B:$B,"<="&$B11)) -> -0.29256061 | AB11: =IF(COUNTIFS(monthly!T:T,"",monthly!$A:$A,">="&$A11,monthly!$B:$B,"<="&$B11)>0,"NA",AVERAGEIFS(monthly!T:T,monthly!$A:$A,">="&$A11,monthly!$B:$B,"<="&$B11)) -> NA | AC11: =IF(COUNTIFS(monthly!U:U,"",monthly!$A:$A,">="&$A11,monthly!$B:$B,"<="&$B11)>0,"NA",AVERAGEIFS(monthly!U:U,monthly!$A:$A,">="&$A11,monthly!$B:$B,"<="&$B11)) -> NA | AD11: =IF(COUNTIFS(monthly!V:V,"",monthly!$A:$A,">="&$A11,monthly!$B:$B,"<="&$B11)>0,"NA",AVERAGEIFS(monthly!V:V,monthly!$A:$A,">="&$A11,monthly!$B:$B,"<="&$B11)) -> NA | AE11: =IF(COUNTIFS(monthly!W:W,"",monthly!$A:$A,">="&$A11,monthly!$B:$B,"<="&$B11)>0,"NA",AVERAGEIFS(monthly!W:W,monthly!$A:$A,">="&$A11,monthly!$B:$B,"<="&$B11)) -> NA | AF11: =IF(COUNTIFS(monthly!X:X,"",monthly!$A:$A,">="&$A11,monthly!$B:$B,"<="&$B11)>0,"NA",AVERAGEIFS(monthly!X:X,monthly!$A:$A,">="&$A11,monthly!$B:$B,"<="&$B11)) -> NA | AG11: =IF(COUNTIFS(monthly!Y:Y,"",monthly!$A:$A,">="&$A11,monthly!$B:$B,"<="&$B11)>0,"NA",AVERAGEIFS(monthly!Y:Y,monthly!$A:$A,">="&$A11,monthly!$B:$B,"<="&$B11)) -> NA | AH11: =IF(COUNTIFS(monthly!Z:Z,"",monthly!$A:$A,">="&$A11,monthly!$B:$B,"<="&$B11)>0,"NA",AVERAGEIFS(monthly!Z:Z,monthly!$A:$A,">="&$A11,monthly!$B:$B,"<="&$B11)) -> NA
